[20:51:42][MainThread/CRITICAL][exception_hook]:发生异常:
An Fatal Error has occurred: RuntimeError: 训练时发生错误
Traceback (most recent call last):
  at <module> in (f:\python_play\Genshin-analsts\train.py:202)
  at train in (f:\python_play\Genshin-analsts\train.py:142)
failure because of: Exception: 函数 save_model 执行失败
  at train in (f:\python_play\Genshin-analsts\train.py:137)
  at wrapper in (f:\python_play\Genshin-analsts\Decorators.py:24)

