[20:51:42][MainThread/CRITICAL][exception_hook]:发生异常:
An Fatal Error has occurred: RuntimeError: 训练时发生错误
Traceback (most recent call last):
  at <module> in (f:\python_play\Genshin-analsts\train.py:202)
  at train in (f:\python_play\Genshin-analsts\train.py:142)
failure because of: Exception: 函数 save_model 执行失败
  at train in (f:\python_play\Genshin-analsts\train.py:137)
  at wrapper in (f:\python_play\Genshin-analsts\Decorators.py:24)

[21:54:00][MainThread/CRITICAL][exception_hook]:发生异常:
An Fatal Error has occurred: RuntimeError: 训练时发生错误
Traceback (most recent call last):
  at <module> in (f:\python_play\Genshin-analsts\train.py:200)
  at train_continue_with_model in (f:\python_play\Genshin-analsts\train.py:169)
  at train in (f:\python_play\Genshin-analsts\train.py:142)
failure because of: TypeError: time_stretch() takes 1 positional argument but 2 were given
  at train in (f:\python_play\Genshin-analsts\train.py:99)
  at __next__ in (G:\python3.12.2\Lib\site-packages\torch\utils\data\dataloader.py:631)
  at _next_data in (G:\python3.12.2\Lib\site-packages\torch\utils\data\dataloader.py:675)
  at fetch in (G:\python3.12.2\Lib\site-packages\torch\utils\data\_utils\fetch.py:51)
  at __getitem__ in (f:\python_play\Genshin-analsts\Getdata.py:75)
  at __call__ in (f:\python_play\Genshin-analsts\Getdata.py:32)

[21:55:20][MainThread/CRITICAL][exception_hook]:发生异常:
An Fatal Error has occurred: RuntimeError: 训练时发生错误
Traceback (most recent call last):
  at <module> in (f:\python_play\Genshin-analsts\train.py:200)
  at train_continue_with_model in (f:\python_play\Genshin-analsts\train.py:169)
  at train in (f:\python_play\Genshin-analsts\train.py:142)
failure because of: RuntimeError: stack expects each tensor to be equal size, but got [13, 237] at entry 0 and [13, 259] at entry 1
  at train in (f:\python_play\Genshin-analsts\train.py:99)
  at __next__ in (G:\python3.12.2\Lib\site-packages\torch\utils\data\dataloader.py:631)
  at _next_data in (G:\python3.12.2\Lib\site-packages\torch\utils\data\dataloader.py:675)
  at fetch in (G:\python3.12.2\Lib\site-packages\torch\utils\data\_utils\fetch.py:54)
  at default_collate in (G:\python3.12.2\Lib\site-packages\torch\utils\data\_utils\collate.py:277)
  at collate in (G:\python3.12.2\Lib\site-packages\torch\utils\data\_utils\collate.py:144)
  at collate in (G:\python3.12.2\Lib\site-packages\torch\utils\data\_utils\collate.py:121)
  at collate_tensor_fn in (G:\python3.12.2\Lib\site-packages\torch\utils\data\_utils\collate.py:174)

[22:04:11][MainThread/CRITICAL][exception_hook]:发生异常:
An Fatal Error has occurred: RuntimeError: 训练时发生错误
Traceback (most recent call last):
  at <module> in (f:\python_play\Genshin-analsts\train.py:210)
  at train_continue_with_model in (f:\python_play\Genshin-analsts\train.py:179)
  at train in (f:\python_play\Genshin-analsts\train.py:152)
failure because of: RuntimeError: stack expects each tensor to be equal size, but got [13, 209] at entry 0 and [13, 259] at entry 1
  at train in (f:\python_play\Genshin-analsts\train.py:101)
  at __next__ in (G:\python3.12.2\Lib\site-packages\torch\utils\data\dataloader.py:631)
  at _next_data in (G:\python3.12.2\Lib\site-packages\torch\utils\data\dataloader.py:675)
  at fetch in (G:\python3.12.2\Lib\site-packages\torch\utils\data\_utils\fetch.py:54)
  at default_collate in (G:\python3.12.2\Lib\site-packages\torch\utils\data\_utils\collate.py:277)
  at collate in (G:\python3.12.2\Lib\site-packages\torch\utils\data\_utils\collate.py:144)
  at collate in (G:\python3.12.2\Lib\site-packages\torch\utils\data\_utils\collate.py:121)
  at collate_tensor_fn in (G:\python3.12.2\Lib\site-packages\torch\utils\data\_utils\collate.py:174)

[10:41:32][MainThread/CRITICAL][exception_hook]:发生异常:
An Fatal Error has occurred: RuntimeError: 训练时发生错误
Traceback (most recent call last):
  at <module> in (f:\python_play\Genshin-analsts\train.py:210)
  at train_continue_with_model in (f:\python_play\Genshin-analsts\train.py:179)
  at train in (f:\python_play\Genshin-analsts\train.py:152)
failure because of: RuntimeError: stack expects each tensor to be equal size, but got [13, 135] at entry 0 and [13, 259] at entry 1
  at train in (f:\python_play\Genshin-analsts\train.py:101)
  at __next__ in (G:\python3.12.2\Lib\site-packages\torch\utils\data\dataloader.py:631)
  at _next_data in (G:\python3.12.2\Lib\site-packages\torch\utils\data\dataloader.py:675)
  at fetch in (G:\python3.12.2\Lib\site-packages\torch\utils\data\_utils\fetch.py:54)
  at default_collate in (G:\python3.12.2\Lib\site-packages\torch\utils\data\_utils\collate.py:277)
  at collate in (G:\python3.12.2\Lib\site-packages\torch\utils\data\_utils\collate.py:144)
  at collate in (G:\python3.12.2\Lib\site-packages\torch\utils\data\_utils\collate.py:121)
  at collate_tensor_fn in (G:\python3.12.2\Lib\site-packages\torch\utils\data\_utils\collate.py:174)

[10:42:14][MainThread/CRITICAL][exception_hook]:发生异常:
An Fatal Error has occurred: RuntimeError: 训练时发生错误
Traceback (most recent call last):
  at <module> in (f:\python_play\Genshin-analsts\train.py:210)
  at train_continue_with_model in (f:\python_play\Genshin-analsts\train.py:179)
  at train in (f:\python_play\Genshin-analsts\train.py:152)
failure because of: RuntimeError: stack expects each tensor to be equal size, but got [13, 225] at entry 0 and [13, 259] at entry 1
  at train in (f:\python_play\Genshin-analsts\train.py:101)
  at __next__ in (G:\python3.12.2\Lib\site-packages\torch\utils\data\dataloader.py:631)
  at _next_data in (G:\python3.12.2\Lib\site-packages\torch\utils\data\dataloader.py:675)
  at fetch in (G:\python3.12.2\Lib\site-packages\torch\utils\data\_utils\fetch.py:54)
  at default_collate in (G:\python3.12.2\Lib\site-packages\torch\utils\data\_utils\collate.py:277)
  at collate in (G:\python3.12.2\Lib\site-packages\torch\utils\data\_utils\collate.py:144)
  at collate in (G:\python3.12.2\Lib\site-packages\torch\utils\data\_utils\collate.py:121)
  at collate_tensor_fn in (G:\python3.12.2\Lib\site-packages\torch\utils\data\_utils\collate.py:174)

